12.05.2020 15:55 - bot - INFO - Artist "Пугачева" found, user – Xalion

12.05.2020 15:55 - bot - INFO - Artist "парапрпар" not found, user – Xalion

12.05.2020 15:55 - bot - INFO - Track "Этот мир" found, user – Xalion

12.05.2020 15:55 - bot - INFO - Track preview was sent
12.05.2020 15:55 - bot - INFO - Track "jhkglkjhg" not found, user – Xalion

12.05.2020 15:55 - bot - INFO - Artist "drake" found, user – qcqc_meow

12.05.2020 15:55 - bot - INFO - Track "God's plane" found, user – qcqc_meow

12.05.2020 15:57 - TeleBot - ERROR - A request to the Telegram API was unsuccessful. The server returned HTTP 504 Gateway Time-out. Response body:
[b'{"ok":false,"error_code":504,"description":"Gateway Timeout"}']
16.05.2020 14:48 - bot - INFO - Track "ggggg" found, user – Xalion

16.05.2020 14:48 - bot - INFO - Track "fghfg" not found, user – Xalion

16.05.2020 14:50 - bot - INFO - Track "dghyfdgh" not found, user – Xalion

16.05.2020 14:50 - bot - INFO - Artist "vffghfg" not found, user – Xalion

16.05.2020 15:00 - bot - INFO - Artist "Татьяна Буланова" found, user – Xalion

16.05.2020 15:00 - bot - INFO - Track "Не плачь" found, user – Xalion

16.05.2020 15:01 - bot - INFO - Track "Не плачь, татьяна буланова" found, user – Xalion

16.05.2020 15:01 - bot - INFO - Track "белый снег, серыйлед" not found, user – Xalion

16.05.2020 15:01 - bot - INFO - Track "белый снег, серый лед" found, user – Xalion

16.05.2020 15:02 - bot - INFO - Track "ты встречаешь рассвет за игрой в дурака" not found, user – Xalion

16.05.2020 15:03 - bot - INFO - Track "белый лебедь на пруду" not found, user – Xalion

16.05.2020 15:03 - bot - INFO - Track "качает павшую звезду" not found, user – Xalion

16.05.2020 15:04 - bot - INFO - Track "белый лебедь" found, user – Xalion

16.05.2020 15:04 - bot - INFO - Track preview was sent

16.05.2020 15:04 - bot - INFO - Track "Белый лебедь" found, user – Xalion

16.05.2020 15:04 - bot - INFO - Artist "Лесоповал" found, user – Xalion

16.05.2020 15:05 - bot - INFO - Track "белый лебедь лесоповал" not found, user – Xalion

16.05.2020 15:05 - bot - INFO - Track "лесоповал белый лебедь" not found, user – Xalion

16.05.2020 15:06 - bot - INFO - Track "я куплю тебе дом" found, user – Xalion

16.05.2020 15:06 - bot - INFO - Track preview was sent

16.05.2020 15:07 - bot - INFO - Track "Поиск трека" not found, user – Xalion

16.05.2020 15:07 - bot - INFO - Artist "deake" found, user – qcqc_meow

16.05.2020 15:08 - bot - INFO - Artist "jordia" found, user – qcqc_meow

16.05.2020 15:08 - bot - INFO - Artist "sir" found, user – qcqc_meow

16.05.2020 15:08 - bot - INFO - Track "john reccon" found, user – qcqc_meow

16.05.2020 15:08 - bot - INFO - Track preview was sent

16.05.2020 15:08 - bot - INFO - Artist "Поиск трека" not found, user – PifagoRChik

16.05.2020 15:08 - bot - INFO - Track "Супермен" found, user – PifagoRChik

16.05.2020 15:09 - bot - INFO - Track preview was sent

16.05.2020 15:43 - bot - INFO - Artist "fgfggh" not found, user – Xalion

16.05.2020 15:43 - bot - INFO - Artist "кино" found, user – Xalion

16.05.2020 15:43 - bot - INFO - Artist "Буланова" found, user – Xalion

16.05.2020 15:43 - bot - INFO - Artist "Пугачева" found, user – Xalion

16.05.2020 15:43 - bot - INFO - Track "Звезда" found, user – Xalion

16.05.2020 15:43 - bot - INFO - Track "Я кууплю тебе дом" found, user – Xalion

16.05.2020 15:43 - bot - INFO - Track "Этот мир" found, user – Xalion

16.05.2020 15:43 - bot - INFO - Track "Шаман" found, user – Xalion

16.05.2020 15:44 - bot - INFO - Track "У шамана три руки" found, user – Xalion

16.05.2020 15:46 - bot - INFO - Artist "кино" found, user – Xalion

16.05.2020 15:46 - bot - INFO - Artist "буланова" found, user – Xalion

16.05.2020 15:46 - bot - INFO - Artist "лесоповал" found, user – Xalion

16.05.2020 15:46 - bot - INFO - Track "звезда" found, user – Xalion

16.05.2020 15:46 - bot - INFO - Track "у шамана три руки" found, user – Xalion

16.05.2020 15:46 - bot - INFO - Track "этот мир" found, user – Xalion

16.05.2020 16:27 - bot - INFO - Artist "кино" found, user – Xalion

16.05.2020 16:27 - bot - INFO - Artist "буланова" found, user – Xalion

16.05.2020 16:27 - bot - INFO - Track "этот мир" found, user – Xalion

16.05.2020 16:31 - bot - INFO - Artist "дрейк" found, user – Xalion

16.05.2020 16:31 - bot - INFO - Artist "эменем" not found, user – Xalion

16.05.2020 16:31 - bot - INFO - Artist "эминем" found, user – Xalion

16.05.2020 16:31 - bot - INFO - Artist "асап роки" found, user – Xalion

16.05.2020 16:32 - bot - INFO - Track "этот мир" found, user – Xalion

16.05.2020 16:32 - bot - INFO - Track "три руки" found, user – Xalion

16.05.2020 16:35 - bot - INFO - Artist "ю 2" found, user – qcqc_meow

16.05.2020 16:35 - bot - INFO - Artist "somebody" found, user – qcqc_meow

16.05.2020 16:36 - bot - INFO - Track "somebody to love" found, user – qcqc_meow

22.05.2020 14:20 - bot - ERROR - Disconnected, geting new proxy
Traceback (most recent call last):
  File "/Library/Frameworks/Python.framework/Versions/3.8/lib/python3.8/site-packages/urllib3/connectionpool.py", line 426, in _make_request
    six.raise_from(e, None)
  File "<string>", line 3, in raise_from
  File "/Library/Frameworks/Python.framework/Versions/3.8/lib/python3.8/site-packages/urllib3/connectionpool.py", line 421, in _make_request
    httplib_response = conn.getresponse()
  File "/Library/Frameworks/Python.framework/Versions/3.8/lib/python3.8/http/client.py", line 1322, in getresponse
    response.begin()
  File "/Library/Frameworks/Python.framework/Versions/3.8/lib/python3.8/http/client.py", line 303, in begin
    version, status, reason = self._read_status()
  File "/Library/Frameworks/Python.framework/Versions/3.8/lib/python3.8/http/client.py", line 264, in _read_status
    line = str(self.fp.readline(_MAXLINE + 1), "iso-8859-1")
  File "/Library/Frameworks/Python.framework/Versions/3.8/lib/python3.8/socket.py", line 669, in readinto
    return self._sock.recv_into(b)
  File "/Library/Frameworks/Python.framework/Versions/3.8/lib/python3.8/ssl.py", line 1241, in recv_into
    return self.read(nbytes, buffer)
  File "/Library/Frameworks/Python.framework/Versions/3.8/lib/python3.8/ssl.py", line 1099, in read
    return self._sslobj.read(len, buffer)
socket.timeout: The read operation timed out

During handling of the above exception, another exception occurred:

Traceback (most recent call last):
  File "/Library/Frameworks/Python.framework/Versions/3.8/lib/python3.8/site-packages/requests/adapters.py", line 439, in send
    resp = conn.urlopen(
  File "/Library/Frameworks/Python.framework/Versions/3.8/lib/python3.8/site-packages/urllib3/connectionpool.py", line 724, in urlopen
    retries = retries.increment(
  File "/Library/Frameworks/Python.framework/Versions/3.8/lib/python3.8/site-packages/urllib3/util/retry.py", line 403, in increment
    raise six.reraise(type(error), error, _stacktrace)
  File "/Library/Frameworks/Python.framework/Versions/3.8/lib/python3.8/site-packages/urllib3/packages/six.py", line 735, in reraise
    raise value
  File "/Library/Frameworks/Python.framework/Versions/3.8/lib/python3.8/site-packages/urllib3/connectionpool.py", line 670, in urlopen
    httplib_response = self._make_request(
  File "/Library/Frameworks/Python.framework/Versions/3.8/lib/python3.8/site-packages/urllib3/connectionpool.py", line 428, in _make_request
    self._raise_timeout(err=e, url=url, timeout_value=read_timeout)
  File "/Library/Frameworks/Python.framework/Versions/3.8/lib/python3.8/site-packages/urllib3/connectionpool.py", line 335, in _raise_timeout
    raise ReadTimeoutError(
urllib3.exceptions.ReadTimeoutError: HTTPSConnectionPool(host='api.telegram.org', port=443): Read timed out. (read timeout=30)

During handling of the above exception, another exception occurred:

Traceback (most recent call last):
  File "/Users/xalion/Desktop/spotibot_diploma/bot.py", line 99, in <module>
    bot.polling()
  File "/Library/Frameworks/Python.framework/Versions/3.8/lib/python3.8/site-packages/telebot/__init__.py", line 417, in polling
    self.__non_threaded_polling(none_stop, interval, timeout)
  File "/Library/Frameworks/Python.framework/Versions/3.8/lib/python3.8/site-packages/telebot/__init__.py", line 468, in __non_threaded_polling
    self.__retrieve_updates(timeout)
  File "/Library/Frameworks/Python.framework/Versions/3.8/lib/python3.8/site-packages/telebot/__init__.py", line 281, in __retrieve_updates
    updates = self.get_updates(offset=(self.last_update_id + 1), timeout=timeout)
  File "/Library/Frameworks/Python.framework/Versions/3.8/lib/python3.8/site-packages/telebot/__init__.py", line 251, in get_updates
    json_updates = apihelper.get_updates(self.token, offset, limit, timeout, allowed_updates)
  File "/Library/Frameworks/Python.framework/Versions/3.8/lib/python3.8/site-packages/telebot/apihelper.py", line 199, in get_updates
    return _make_request(token, method_url, params=payload)
  File "/Library/Frameworks/Python.framework/Versions/3.8/lib/python3.8/site-packages/telebot/apihelper.py", line 62, in _make_request
    result = _get_req_session().request(method, request_url, params=params, files=files,
  File "/Library/Frameworks/Python.framework/Versions/3.8/lib/python3.8/site-packages/requests/sessions.py", line 530, in request
    resp = self.send(prep, **send_kwargs)
  File "/Library/Frameworks/Python.framework/Versions/3.8/lib/python3.8/site-packages/requests/sessions.py", line 643, in send
    r = adapter.send(request, **kwargs)
  File "/Library/Frameworks/Python.framework/Versions/3.8/lib/python3.8/site-packages/requests/adapters.py", line 529, in send
    raise ReadTimeout(e, request=request)
requests.exceptions.ReadTimeout: HTTPSConnectionPool(host='api.telegram.org', port=443): Read timed out. (read timeout=30)
22.05.2020 14:20 - bot - INFO - Connect to a new proxy, ip – 169.57.157.146

22.05.2020 14:21 - bot - ERROR - Disconnected, geting new proxy
Traceback (most recent call last):
  File "/Library/Frameworks/Python.framework/Versions/3.8/lib/python3.8/site-packages/urllib3/connectionpool.py", line 667, in urlopen
    self._prepare_proxy(conn)
  File "/Library/Frameworks/Python.framework/Versions/3.8/lib/python3.8/site-packages/urllib3/connectionpool.py", line 930, in _prepare_proxy
    conn.connect()
  File "/Library/Frameworks/Python.framework/Versions/3.8/lib/python3.8/site-packages/urllib3/connection.py", line 316, in connect
    self._tunnel()
  File "/Library/Frameworks/Python.framework/Versions/3.8/lib/python3.8/http/client.py", line 898, in _tunnel
    raise OSError("Tunnel connection failed: %d %s" % (code,
OSError: Tunnel connection failed: 403 Forbidden

During handling of the above exception, another exception occurred:

Traceback (most recent call last):
  File "/Library/Frameworks/Python.framework/Versions/3.8/lib/python3.8/site-packages/requests/adapters.py", line 439, in send
    resp = conn.urlopen(
  File "/Library/Frameworks/Python.framework/Versions/3.8/lib/python3.8/site-packages/urllib3/connectionpool.py", line 724, in urlopen
    retries = retries.increment(
  File "/Library/Frameworks/Python.framework/Versions/3.8/lib/python3.8/site-packages/urllib3/util/retry.py", line 439, in increment
    raise MaxRetryError(_pool, url, error or ResponseError(cause))
urllib3.exceptions.MaxRetryError: HTTPSConnectionPool(host='api.telegram.org', port=443): Max retries exceeded with url: /bot940145749:AAENwzTWDnBkbCXwJZ8Fw7XdS0GCM5CgZoU/getUpdates?offset=1&timeout=20 (Caused by ProxyError('Cannot connect to proxy.', OSError('Tunnel connection failed: 403 Forbidden')))

During handling of the above exception, another exception occurred:

Traceback (most recent call last):
  File "/Users/xalion/Desktop/spotibot_diploma/bot.py", line 99, in <module>
    bot.polling()
  File "/Library/Frameworks/Python.framework/Versions/3.8/lib/python3.8/site-packages/telebot/__init__.py", line 417, in polling
    self.__non_threaded_polling(none_stop, interval, timeout)
  File "/Library/Frameworks/Python.framework/Versions/3.8/lib/python3.8/site-packages/telebot/__init__.py", line 468, in __non_threaded_polling
    self.__retrieve_updates(timeout)
  File "/Library/Frameworks/Python.framework/Versions/3.8/lib/python3.8/site-packages/telebot/__init__.py", line 281, in __retrieve_updates
    updates = self.get_updates(offset=(self.last_update_id + 1), timeout=timeout)
  File "/Library/Frameworks/Python.framework/Versions/3.8/lib/python3.8/site-packages/telebot/__init__.py", line 251, in get_updates
    json_updates = apihelper.get_updates(self.token, offset, limit, timeout, allowed_updates)
  File "/Library/Frameworks/Python.framework/Versions/3.8/lib/python3.8/site-packages/telebot/apihelper.py", line 199, in get_updates
    return _make_request(token, method_url, params=payload)
  File "/Library/Frameworks/Python.framework/Versions/3.8/lib/python3.8/site-packages/telebot/apihelper.py", line 62, in _make_request
    result = _get_req_session().request(method, request_url, params=params, files=files,
  File "/Library/Frameworks/Python.framework/Versions/3.8/lib/python3.8/site-packages/requests/sessions.py", line 530, in request
    resp = self.send(prep, **send_kwargs)
  File "/Library/Frameworks/Python.framework/Versions/3.8/lib/python3.8/site-packages/requests/sessions.py", line 643, in send
    r = adapter.send(request, **kwargs)
  File "/Library/Frameworks/Python.framework/Versions/3.8/lib/python3.8/site-packages/requests/adapters.py", line 510, in send
    raise ProxyError(e, request=request)
requests.exceptions.ProxyError: HTTPSConnectionPool(host='api.telegram.org', port=443): Max retries exceeded with url: /bot940145749:AAENwzTWDnBkbCXwJZ8Fw7XdS0GCM5CgZoU/getUpdates?offset=1&timeout=20 (Caused by ProxyError('Cannot connect to proxy.', OSError('Tunnel connection failed: 403 Forbidden')))
22.05.2020 14:21 - bot - INFO - Connect to a new proxy, ip – 37.220.195.14

22.05.2020 14:21 - bot - ERROR - Disconnected, geting new proxy
Traceback (most recent call last):
  File "/Library/Frameworks/Python.framework/Versions/3.8/lib/python3.8/site-packages/urllib3/connectionpool.py", line 667, in urlopen
    self._prepare_proxy(conn)
  File "/Library/Frameworks/Python.framework/Versions/3.8/lib/python3.8/site-packages/urllib3/connectionpool.py", line 930, in _prepare_proxy
    conn.connect()
  File "/Library/Frameworks/Python.framework/Versions/3.8/lib/python3.8/site-packages/urllib3/connection.py", line 316, in connect
    self._tunnel()
  File "/Library/Frameworks/Python.framework/Versions/3.8/lib/python3.8/http/client.py", line 894, in _tunnel
    (version, code, message) = response._read_status()
  File "/Library/Frameworks/Python.framework/Versions/3.8/lib/python3.8/http/client.py", line 264, in _read_status
    line = str(self.fp.readline(_MAXLINE + 1), "iso-8859-1")
  File "/Library/Frameworks/Python.framework/Versions/3.8/lib/python3.8/socket.py", line 669, in readinto
    return self._sock.recv_into(b)
socket.timeout: timed out

During handling of the above exception, another exception occurred:

Traceback (most recent call last):
  File "/Library/Frameworks/Python.framework/Versions/3.8/lib/python3.8/site-packages/requests/adapters.py", line 439, in send
    resp = conn.urlopen(
  File "/Library/Frameworks/Python.framework/Versions/3.8/lib/python3.8/site-packages/urllib3/connectionpool.py", line 724, in urlopen
    retries = retries.increment(
  File "/Library/Frameworks/Python.framework/Versions/3.8/lib/python3.8/site-packages/urllib3/util/retry.py", line 439, in increment
    raise MaxRetryError(_pool, url, error or ResponseError(cause))
urllib3.exceptions.MaxRetryError: HTTPSConnectionPool(host='api.telegram.org', port=443): Max retries exceeded with url: /bot940145749:AAENwzTWDnBkbCXwJZ8Fw7XdS0GCM5CgZoU/getUpdates?offset=1&timeout=20 (Caused by ProxyError('Cannot connect to proxy.', timeout('timed out')))

During handling of the above exception, another exception occurred:

Traceback (most recent call last):
  File "/Users/xalion/Desktop/spotibot_diploma/bot.py", line 99, in <module>
    bot.polling()
  File "/Library/Frameworks/Python.framework/Versions/3.8/lib/python3.8/site-packages/telebot/__init__.py", line 417, in polling
    self.__non_threaded_polling(none_stop, interval, timeout)
  File "/Library/Frameworks/Python.framework/Versions/3.8/lib/python3.8/site-packages/telebot/__init__.py", line 468, in __non_threaded_polling
    self.__retrieve_updates(timeout)
  File "/Library/Frameworks/Python.framework/Versions/3.8/lib/python3.8/site-packages/telebot/__init__.py", line 281, in __retrieve_updates
    updates = self.get_updates(offset=(self.last_update_id + 1), timeout=timeout)
  File "/Library/Frameworks/Python.framework/Versions/3.8/lib/python3.8/site-packages/telebot/__init__.py", line 251, in get_updates
    json_updates = apihelper.get_updates(self.token, offset, limit, timeout, allowed_updates)
  File "/Library/Frameworks/Python.framework/Versions/3.8/lib/python3.8/site-packages/telebot/apihelper.py", line 199, in get_updates
    return _make_request(token, method_url, params=payload)
  File "/Library/Frameworks/Python.framework/Versions/3.8/lib/python3.8/site-packages/telebot/apihelper.py", line 62, in _make_request
    result = _get_req_session().request(method, request_url, params=params, files=files,
  File "/Library/Frameworks/Python.framework/Versions/3.8/lib/python3.8/site-packages/requests/sessions.py", line 530, in request
    resp = self.send(prep, **send_kwargs)
  File "/Library/Frameworks/Python.framework/Versions/3.8/lib/python3.8/site-packages/requests/sessions.py", line 643, in send
    r = adapter.send(request, **kwargs)
  File "/Library/Frameworks/Python.framework/Versions/3.8/lib/python3.8/site-packages/requests/adapters.py", line 510, in send
    raise ProxyError(e, request=request)
requests.exceptions.ProxyError: HTTPSConnectionPool(host='api.telegram.org', port=443): Max retries exceeded with url: /bot940145749:AAENwzTWDnBkbCXwJZ8Fw7XdS0GCM5CgZoU/getUpdates?offset=1&timeout=20 (Caused by ProxyError('Cannot connect to proxy.', timeout('timed out')))
22.05.2020 14:21 - bot - INFO - Connect to a new proxy, ip – 52.179.231.206

22.05.2020 14:23 - bot - ERROR - Disconnected, geting new proxy
Traceback (most recent call last):
  File "/Library/Frameworks/Python.framework/Versions/3.8/lib/python3.8/site-packages/urllib3/connectionpool.py", line 667, in urlopen
    self._prepare_proxy(conn)
  File "/Library/Frameworks/Python.framework/Versions/3.8/lib/python3.8/site-packages/urllib3/connectionpool.py", line 930, in _prepare_proxy
    conn.connect()
  File "/Library/Frameworks/Python.framework/Versions/3.8/lib/python3.8/site-packages/urllib3/connection.py", line 316, in connect
    self._tunnel()
  File "/Library/Frameworks/Python.framework/Versions/3.8/lib/python3.8/http/client.py", line 898, in _tunnel
    raise OSError("Tunnel connection failed: %d %s" % (code,
OSError: Tunnel connection failed: 462 status code 462

During handling of the above exception, another exception occurred:

Traceback (most recent call last):
  File "/Library/Frameworks/Python.framework/Versions/3.8/lib/python3.8/site-packages/requests/adapters.py", line 439, in send
    resp = conn.urlopen(
  File "/Library/Frameworks/Python.framework/Versions/3.8/lib/python3.8/site-packages/urllib3/connectionpool.py", line 724, in urlopen
    retries = retries.increment(
  File "/Library/Frameworks/Python.framework/Versions/3.8/lib/python3.8/site-packages/urllib3/util/retry.py", line 439, in increment
    raise MaxRetryError(_pool, url, error or ResponseError(cause))
urllib3.exceptions.MaxRetryError: HTTPSConnectionPool(host='api.telegram.org', port=443): Max retries exceeded with url: /bot940145749:AAENwzTWDnBkbCXwJZ8Fw7XdS0GCM5CgZoU/getUpdates?offset=1&timeout=20 (Caused by ProxyError('Cannot connect to proxy.', OSError('Tunnel connection failed: 462 status code 462')))

During handling of the above exception, another exception occurred:

Traceback (most recent call last):
  File "/Users/xalion/Desktop/spotibot_diploma/bot.py", line 100, in <module>
    bot.polling()
  File "/Library/Frameworks/Python.framework/Versions/3.8/lib/python3.8/site-packages/telebot/__init__.py", line 417, in polling
    self.__non_threaded_polling(none_stop, interval, timeout)
  File "/Library/Frameworks/Python.framework/Versions/3.8/lib/python3.8/site-packages/telebot/__init__.py", line 468, in __non_threaded_polling
    self.__retrieve_updates(timeout)
  File "/Library/Frameworks/Python.framework/Versions/3.8/lib/python3.8/site-packages/telebot/__init__.py", line 281, in __retrieve_updates
    updates = self.get_updates(offset=(self.last_update_id + 1), timeout=timeout)
  File "/Library/Frameworks/Python.framework/Versions/3.8/lib/python3.8/site-packages/telebot/__init__.py", line 251, in get_updates
    json_updates = apihelper.get_updates(self.token, offset, limit, timeout, allowed_updates)
  File "/Library/Frameworks/Python.framework/Versions/3.8/lib/python3.8/site-packages/telebot/apihelper.py", line 199, in get_updates
    return _make_request(token, method_url, params=payload)
  File "/Library/Frameworks/Python.framework/Versions/3.8/lib/python3.8/site-packages/telebot/apihelper.py", line 62, in _make_request
    result = _get_req_session().request(method, request_url, params=params, files=files,
  File "/Library/Frameworks/Python.framework/Versions/3.8/lib/python3.8/site-packages/requests/sessions.py", line 530, in request
    resp = self.send(prep, **send_kwargs)
  File "/Library/Frameworks/Python.framework/Versions/3.8/lib/python3.8/site-packages/requests/sessions.py", line 643, in send
    r = adapter.send(request, **kwargs)
  File "/Library/Frameworks/Python.framework/Versions/3.8/lib/python3.8/site-packages/requests/adapters.py", line 510, in send
    raise ProxyError(e, request=request)
requests.exceptions.ProxyError: HTTPSConnectionPool(host='api.telegram.org', port=443): Max retries exceeded with url: /bot940145749:AAENwzTWDnBkbCXwJZ8Fw7XdS0GCM5CgZoU/getUpdates?offset=1&timeout=20 (Caused by ProxyError('Cannot connect to proxy.', OSError('Tunnel connection failed: 462 status code 462')))
22.05.2020 14:23 - bot - INFO - Connect to a new proxy, ip – 188.226.141.61

22.05.2020 14:23 - bot - ERROR - Disconnected, geting new proxy
Traceback (most recent call last):
  File "/Library/Frameworks/Python.framework/Versions/3.8/lib/python3.8/site-packages/urllib3/connectionpool.py", line 667, in urlopen
    self._prepare_proxy(conn)
  File "/Library/Frameworks/Python.framework/Versions/3.8/lib/python3.8/site-packages/urllib3/connectionpool.py", line 930, in _prepare_proxy
    conn.connect()
  File "/Library/Frameworks/Python.framework/Versions/3.8/lib/python3.8/site-packages/urllib3/connection.py", line 316, in connect
    self._tunnel()
  File "/Library/Frameworks/Python.framework/Versions/3.8/lib/python3.8/http/client.py", line 898, in _tunnel
    raise OSError("Tunnel connection failed: %d %s" % (code,
OSError: Tunnel connection failed: 400 Bad Request

During handling of the above exception, another exception occurred:

Traceback (most recent call last):
  File "/Library/Frameworks/Python.framework/Versions/3.8/lib/python3.8/site-packages/requests/adapters.py", line 439, in send
    resp = conn.urlopen(
  File "/Library/Frameworks/Python.framework/Versions/3.8/lib/python3.8/site-packages/urllib3/connectionpool.py", line 724, in urlopen
    retries = retries.increment(
  File "/Library/Frameworks/Python.framework/Versions/3.8/lib/python3.8/site-packages/urllib3/util/retry.py", line 439, in increment
    raise MaxRetryError(_pool, url, error or ResponseError(cause))
urllib3.exceptions.MaxRetryError: HTTPSConnectionPool(host='api.telegram.org', port=443): Max retries exceeded with url: /bot940145749:AAENwzTWDnBkbCXwJZ8Fw7XdS0GCM5CgZoU/getUpdates?offset=1&timeout=20 (Caused by ProxyError('Cannot connect to proxy.', OSError('Tunnel connection failed: 400 Bad Request')))

During handling of the above exception, another exception occurred:

Traceback (most recent call last):
  File "/Users/xalion/Desktop/spotibot_diploma/bot.py", line 100, in <module>
    bot.polling()
  File "/Library/Frameworks/Python.framework/Versions/3.8/lib/python3.8/site-packages/telebot/__init__.py", line 417, in polling
    self.__non_threaded_polling(none_stop, interval, timeout)
  File "/Library/Frameworks/Python.framework/Versions/3.8/lib/python3.8/site-packages/telebot/__init__.py", line 468, in __non_threaded_polling
    self.__retrieve_updates(timeout)
  File "/Library/Frameworks/Python.framework/Versions/3.8/lib/python3.8/site-packages/telebot/__init__.py", line 281, in __retrieve_updates
    updates = self.get_updates(offset=(self.last_update_id + 1), timeout=timeout)
  File "/Library/Frameworks/Python.framework/Versions/3.8/lib/python3.8/site-packages/telebot/__init__.py", line 251, in get_updates
    json_updates = apihelper.get_updates(self.token, offset, limit, timeout, allowed_updates)
  File "/Library/Frameworks/Python.framework/Versions/3.8/lib/python3.8/site-packages/telebot/apihelper.py", line 199, in get_updates
    return _make_request(token, method_url, params=payload)
  File "/Library/Frameworks/Python.framework/Versions/3.8/lib/python3.8/site-packages/telebot/apihelper.py", line 62, in _make_request
    result = _get_req_session().request(method, request_url, params=params, files=files,
  File "/Library/Frameworks/Python.framework/Versions/3.8/lib/python3.8/site-packages/requests/sessions.py", line 530, in request
    resp = self.send(prep, **send_kwargs)
  File "/Library/Frameworks/Python.framework/Versions/3.8/lib/python3.8/site-packages/requests/sessions.py", line 643, in send
    r = adapter.send(request, **kwargs)
  File "/Library/Frameworks/Python.framework/Versions/3.8/lib/python3.8/site-packages/requests/adapters.py", line 510, in send
    raise ProxyError(e, request=request)
requests.exceptions.ProxyError: HTTPSConnectionPool(host='api.telegram.org', port=443): Max retries exceeded with url: /bot940145749:AAENwzTWDnBkbCXwJZ8Fw7XdS0GCM5CgZoU/getUpdates?offset=1&timeout=20 (Caused by ProxyError('Cannot connect to proxy.', OSError('Tunnel connection failed: 400 Bad Request')))
22.05.2020 14:23 - bot - INFO - Connect to a new proxy, ip – 58.61.154.153

22.05.2020 14:23 - bot - ERROR - Disconnected, geting new proxy
Traceback (most recent call last):
  File "/Library/Frameworks/Python.framework/Versions/3.8/lib/python3.8/site-packages/urllib3/connectionpool.py", line 667, in urlopen
    self._prepare_proxy(conn)
  File "/Library/Frameworks/Python.framework/Versions/3.8/lib/python3.8/site-packages/urllib3/connectionpool.py", line 930, in _prepare_proxy
    conn.connect()
  File "/Library/Frameworks/Python.framework/Versions/3.8/lib/python3.8/site-packages/urllib3/connection.py", line 316, in connect
    self._tunnel()
  File "/Library/Frameworks/Python.framework/Versions/3.8/lib/python3.8/http/client.py", line 894, in _tunnel
    (version, code, message) = response._read_status()
  File "/Library/Frameworks/Python.framework/Versions/3.8/lib/python3.8/http/client.py", line 264, in _read_status
    line = str(self.fp.readline(_MAXLINE + 1), "iso-8859-1")
  File "/Library/Frameworks/Python.framework/Versions/3.8/lib/python3.8/socket.py", line 669, in readinto
    return self._sock.recv_into(b)
socket.timeout: timed out

During handling of the above exception, another exception occurred:

Traceback (most recent call last):
  File "/Library/Frameworks/Python.framework/Versions/3.8/lib/python3.8/site-packages/requests/adapters.py", line 439, in send
    resp = conn.urlopen(
  File "/Library/Frameworks/Python.framework/Versions/3.8/lib/python3.8/site-packages/urllib3/connectionpool.py", line 724, in urlopen
    retries = retries.increment(
  File "/Library/Frameworks/Python.framework/Versions/3.8/lib/python3.8/site-packages/urllib3/util/retry.py", line 439, in increment
    raise MaxRetryError(_pool, url, error or ResponseError(cause))
urllib3.exceptions.MaxRetryError: HTTPSConnectionPool(host='api.telegram.org', port=443): Max retries exceeded with url: /bot940145749:AAENwzTWDnBkbCXwJZ8Fw7XdS0GCM5CgZoU/getUpdates?offset=1&timeout=20 (Caused by ProxyError('Cannot connect to proxy.', timeout('timed out')))

During handling of the above exception, another exception occurred:

Traceback (most recent call last):
  File "/Users/xalion/Desktop/spotibot_diploma/bot.py", line 100, in <module>
    bot.polling()
  File "/Library/Frameworks/Python.framework/Versions/3.8/lib/python3.8/site-packages/telebot/__init__.py", line 417, in polling
    self.__non_threaded_polling(none_stop, interval, timeout)
  File "/Library/Frameworks/Python.framework/Versions/3.8/lib/python3.8/site-packages/telebot/__init__.py", line 468, in __non_threaded_polling
    self.__retrieve_updates(timeout)
  File "/Library/Frameworks/Python.framework/Versions/3.8/lib/python3.8/site-packages/telebot/__init__.py", line 281, in __retrieve_updates
    updates = self.get_updates(offset=(self.last_update_id + 1), timeout=timeout)
  File "/Library/Frameworks/Python.framework/Versions/3.8/lib/python3.8/site-packages/telebot/__init__.py", line 251, in get_updates
    json_updates = apihelper.get_updates(self.token, offset, limit, timeout, allowed_updates)
  File "/Library/Frameworks/Python.framework/Versions/3.8/lib/python3.8/site-packages/telebot/apihelper.py", line 199, in get_updates
    return _make_request(token, method_url, params=payload)
  File "/Library/Frameworks/Python.framework/Versions/3.8/lib/python3.8/site-packages/telebot/apihelper.py", line 62, in _make_request
    result = _get_req_session().request(method, request_url, params=params, files=files,
  File "/Library/Frameworks/Python.framework/Versions/3.8/lib/python3.8/site-packages/requests/sessions.py", line 530, in request
    resp = self.send(prep, **send_kwargs)
  File "/Library/Frameworks/Python.framework/Versions/3.8/lib/python3.8/site-packages/requests/sessions.py", line 643, in send
    r = adapter.send(request, **kwargs)
  File "/Library/Frameworks/Python.framework/Versions/3.8/lib/python3.8/site-packages/requests/adapters.py", line 510, in send
    raise ProxyError(e, request=request)
requests.exceptions.ProxyError: HTTPSConnectionPool(host='api.telegram.org', port=443): Max retries exceeded with url: /bot940145749:AAENwzTWDnBkbCXwJZ8Fw7XdS0GCM5CgZoU/getUpdates?offset=1&timeout=20 (Caused by ProxyError('Cannot connect to proxy.', timeout('timed out')))
22.05.2020 14:23 - bot - INFO - Connect to a new proxy, ip – 36.37.81.135

22.05.2020 14:23 - bot - ERROR - Disconnected, geting new proxy
Traceback (most recent call last):
  File "/Library/Frameworks/Python.framework/Versions/3.8/lib/python3.8/site-packages/urllib3/connection.py", line 159, in _new_conn
    conn = connection.create_connection(
  File "/Library/Frameworks/Python.framework/Versions/3.8/lib/python3.8/site-packages/urllib3/util/connection.py", line 84, in create_connection
    raise err
  File "/Library/Frameworks/Python.framework/Versions/3.8/lib/python3.8/site-packages/urllib3/util/connection.py", line 74, in create_connection
    sock.connect(sa)
socket.timeout: timed out

During handling of the above exception, another exception occurred:

Traceback (most recent call last):
  File "/Library/Frameworks/Python.framework/Versions/3.8/lib/python3.8/site-packages/urllib3/connectionpool.py", line 667, in urlopen
    self._prepare_proxy(conn)
  File "/Library/Frameworks/Python.framework/Versions/3.8/lib/python3.8/site-packages/urllib3/connectionpool.py", line 930, in _prepare_proxy
    conn.connect()
  File "/Library/Frameworks/Python.framework/Versions/3.8/lib/python3.8/site-packages/urllib3/connection.py", line 308, in connect
    conn = self._new_conn()
  File "/Library/Frameworks/Python.framework/Versions/3.8/lib/python3.8/site-packages/urllib3/connection.py", line 164, in _new_conn
    raise ConnectTimeoutError(
urllib3.exceptions.ConnectTimeoutError: (<urllib3.connection.HTTPSConnection object at 0x102e188e0>, 'Connection to 36.37.81.135 timed out. (connect timeout=3.5)')

During handling of the above exception, another exception occurred:

Traceback (most recent call last):
  File "/Library/Frameworks/Python.framework/Versions/3.8/lib/python3.8/site-packages/requests/adapters.py", line 439, in send
    resp = conn.urlopen(
  File "/Library/Frameworks/Python.framework/Versions/3.8/lib/python3.8/site-packages/urllib3/connectionpool.py", line 724, in urlopen
    retries = retries.increment(
  File "/Library/Frameworks/Python.framework/Versions/3.8/lib/python3.8/site-packages/urllib3/util/retry.py", line 439, in increment
    raise MaxRetryError(_pool, url, error or ResponseError(cause))
urllib3.exceptions.MaxRetryError: HTTPSConnectionPool(host='api.telegram.org', port=443): Max retries exceeded with url: /bot940145749:AAENwzTWDnBkbCXwJZ8Fw7XdS0GCM5CgZoU/getUpdates?offset=1&timeout=20 (Caused by ConnectTimeoutError(<urllib3.connection.HTTPSConnection object at 0x102e188e0>, 'Connection to 36.37.81.135 timed out. (connect timeout=3.5)'))

During handling of the above exception, another exception occurred:

Traceback (most recent call last):
  File "/Users/xalion/Desktop/spotibot_diploma/bot.py", line 100, in <module>
    bot.polling()
  File "/Library/Frameworks/Python.framework/Versions/3.8/lib/python3.8/site-packages/telebot/__init__.py", line 417, in polling
    self.__non_threaded_polling(none_stop, interval, timeout)
  File "/Library/Frameworks/Python.framework/Versions/3.8/lib/python3.8/site-packages/telebot/__init__.py", line 468, in __non_threaded_polling
    self.__retrieve_updates(timeout)
  File "/Library/Frameworks/Python.framework/Versions/3.8/lib/python3.8/site-packages/telebot/__init__.py", line 281, in __retrieve_updates
    updates = self.get_updates(offset=(self.last_update_id + 1), timeout=timeout)
  File "/Library/Frameworks/Python.framework/Versions/3.8/lib/python3.8/site-packages/telebot/__init__.py", line 251, in get_updates
    json_updates = apihelper.get_updates(self.token, offset, limit, timeout, allowed_updates)
  File "/Library/Frameworks/Python.framework/Versions/3.8/lib/python3.8/site-packages/telebot/apihelper.py", line 199, in get_updates
    return _make_request(token, method_url, params=payload)
  File "/Library/Frameworks/Python.framework/Versions/3.8/lib/python3.8/site-packages/telebot/apihelper.py", line 62, in _make_request
    result = _get_req_session().request(method, request_url, params=params, files=files,
  File "/Library/Frameworks/Python.framework/Versions/3.8/lib/python3.8/site-packages/requests/sessions.py", line 530, in request
    resp = self.send(prep, **send_kwargs)
  File "/Library/Frameworks/Python.framework/Versions/3.8/lib/python3.8/site-packages/requests/sessions.py", line 643, in send
    r = adapter.send(request, **kwargs)
  File "/Library/Frameworks/Python.framework/Versions/3.8/lib/python3.8/site-packages/requests/adapters.py", line 504, in send
    raise ConnectTimeout(e, request=request)
requests.exceptions.ConnectTimeout: HTTPSConnectionPool(host='api.telegram.org', port=443): Max retries exceeded with url: /bot940145749:AAENwzTWDnBkbCXwJZ8Fw7XdS0GCM5CgZoU/getUpdates?offset=1&timeout=20 (Caused by ConnectTimeoutError(<urllib3.connection.HTTPSConnection object at 0x102e188e0>, 'Connection to 36.37.81.135 timed out. (connect timeout=3.5)'))
22.05.2020 14:23 - bot - INFO - Connect to a new proxy, ip – 88.99.10.252

22.05.2020 14:23 - bot - ERROR - Disconnected, geting new proxy
Traceback (most recent call last):
  File "/Library/Frameworks/Python.framework/Versions/3.8/lib/python3.8/site-packages/urllib3/connectionpool.py", line 667, in urlopen
    self._prepare_proxy(conn)
  File "/Library/Frameworks/Python.framework/Versions/3.8/lib/python3.8/site-packages/urllib3/connectionpool.py", line 930, in _prepare_proxy
    conn.connect()
  File "/Library/Frameworks/Python.framework/Versions/3.8/lib/python3.8/site-packages/urllib3/connection.py", line 361, in connect
    self.sock = ssl_wrap_socket(
  File "/Library/Frameworks/Python.framework/Versions/3.8/lib/python3.8/site-packages/urllib3/util/ssl_.py", line 377, in ssl_wrap_socket
    return context.wrap_socket(sock, server_hostname=server_hostname)
  File "/Library/Frameworks/Python.framework/Versions/3.8/lib/python3.8/ssl.py", line 500, in wrap_socket
    return self.sslsocket_class._create(
  File "/Library/Frameworks/Python.framework/Versions/3.8/lib/python3.8/ssl.py", line 1040, in _create
    self.do_handshake()
  File "/Library/Frameworks/Python.framework/Versions/3.8/lib/python3.8/ssl.py", line 1309, in do_handshake
    self._sslobj.do_handshake()
ssl.SSLCertVerificationError: [SSL: CERTIFICATE_VERIFY_FAILED] certificate verify failed: self signed certificate in certificate chain (_ssl.c:1108)

During handling of the above exception, another exception occurred:

Traceback (most recent call last):
  File "/Library/Frameworks/Python.framework/Versions/3.8/lib/python3.8/site-packages/requests/adapters.py", line 439, in send
    resp = conn.urlopen(
  File "/Library/Frameworks/Python.framework/Versions/3.8/lib/python3.8/site-packages/urllib3/connectionpool.py", line 724, in urlopen
    retries = retries.increment(
  File "/Library/Frameworks/Python.framework/Versions/3.8/lib/python3.8/site-packages/urllib3/util/retry.py", line 439, in increment
    raise MaxRetryError(_pool, url, error or ResponseError(cause))
urllib3.exceptions.MaxRetryError: HTTPSConnectionPool(host='api.telegram.org', port=443): Max retries exceeded with url: /bot940145749:AAENwzTWDnBkbCXwJZ8Fw7XdS0GCM5CgZoU/getUpdates?offset=1&timeout=20 (Caused by SSLError(SSLCertVerificationError(1, '[SSL: CERTIFICATE_VERIFY_FAILED] certificate verify failed: self signed certificate in certificate chain (_ssl.c:1108)')))

During handling of the above exception, another exception occurred:

Traceback (most recent call last):
  File "/Users/xalion/Desktop/spotibot_diploma/bot.py", line 100, in <module>
    bot.polling()
  File "/Library/Frameworks/Python.framework/Versions/3.8/lib/python3.8/site-packages/telebot/__init__.py", line 417, in polling
    self.__non_threaded_polling(none_stop, interval, timeout)
  File "/Library/Frameworks/Python.framework/Versions/3.8/lib/python3.8/site-packages/telebot/__init__.py", line 468, in __non_threaded_polling
    self.__retrieve_updates(timeout)
  File "/Library/Frameworks/Python.framework/Versions/3.8/lib/python3.8/site-packages/telebot/__init__.py", line 281, in __retrieve_updates
    updates = self.get_updates(offset=(self.last_update_id + 1), timeout=timeout)
  File "/Library/Frameworks/Python.framework/Versions/3.8/lib/python3.8/site-packages/telebot/__init__.py", line 251, in get_updates
    json_updates = apihelper.get_updates(self.token, offset, limit, timeout, allowed_updates)
  File "/Library/Frameworks/Python.framework/Versions/3.8/lib/python3.8/site-packages/telebot/apihelper.py", line 199, in get_updates
    return _make_request(token, method_url, params=payload)
  File "/Library/Frameworks/Python.framework/Versions/3.8/lib/python3.8/site-packages/telebot/apihelper.py", line 62, in _make_request
    result = _get_req_session().request(method, request_url, params=params, files=files,
  File "/Library/Frameworks/Python.framework/Versions/3.8/lib/python3.8/site-packages/requests/sessions.py", line 530, in request
    resp = self.send(prep, **send_kwargs)
  File "/Library/Frameworks/Python.framework/Versions/3.8/lib/python3.8/site-packages/requests/sessions.py", line 643, in send
    r = adapter.send(request, **kwargs)
  File "/Library/Frameworks/Python.framework/Versions/3.8/lib/python3.8/site-packages/requests/adapters.py", line 514, in send
    raise SSLError(e, request=request)
requests.exceptions.SSLError: HTTPSConnectionPool(host='api.telegram.org', port=443): Max retries exceeded with url: /bot940145749:AAENwzTWDnBkbCXwJZ8Fw7XdS0GCM5CgZoU/getUpdates?offset=1&timeout=20 (Caused by SSLError(SSLCertVerificationError(1, '[SSL: CERTIFICATE_VERIFY_FAILED] certificate verify failed: self signed certificate in certificate chain (_ssl.c:1108)')))
22.05.2020 14:23 - bot - INFO - Connect to a new proxy, ip – 148.244.118.227

22.05.2020 14:23 - bot - ERROR - Disconnected, geting new proxy
Traceback (most recent call last):
  File "/Library/Frameworks/Python.framework/Versions/3.8/lib/python3.8/site-packages/urllib3/connectionpool.py", line 667, in urlopen
    self._prepare_proxy(conn)
  File "/Library/Frameworks/Python.framework/Versions/3.8/lib/python3.8/site-packages/urllib3/connectionpool.py", line 930, in _prepare_proxy
    conn.connect()
  File "/Library/Frameworks/Python.framework/Versions/3.8/lib/python3.8/site-packages/urllib3/connection.py", line 316, in connect
    self._tunnel()
  File "/Library/Frameworks/Python.framework/Versions/3.8/lib/python3.8/http/client.py", line 898, in _tunnel
    raise OSError("Tunnel connection failed: %d %s" % (code,
OSError: Tunnel connection failed: 403 Forbidden

During handling of the above exception, another exception occurred:

Traceback (most recent call last):
  File "/Library/Frameworks/Python.framework/Versions/3.8/lib/python3.8/site-packages/requests/adapters.py", line 439, in send
    resp = conn.urlopen(
  File "/Library/Frameworks/Python.framework/Versions/3.8/lib/python3.8/site-packages/urllib3/connectionpool.py", line 724, in urlopen
    retries = retries.increment(
  File "/Library/Frameworks/Python.framework/Versions/3.8/lib/python3.8/site-packages/urllib3/util/retry.py", line 439, in increment
    raise MaxRetryError(_pool, url, error or ResponseError(cause))
urllib3.exceptions.MaxRetryError: HTTPSConnectionPool(host='api.telegram.org', port=443): Max retries exceeded with url: /bot940145749:AAENwzTWDnBkbCXwJZ8Fw7XdS0GCM5CgZoU/getUpdates?offset=1&timeout=20 (Caused by ProxyError('Cannot connect to proxy.', OSError('Tunnel connection failed: 403 Forbidden')))

During handling of the above exception, another exception occurred:

Traceback (most recent call last):
  File "/Users/xalion/Desktop/spotibot_diploma/bot.py", line 100, in <module>
    bot.polling()
  File "/Library/Frameworks/Python.framework/Versions/3.8/lib/python3.8/site-packages/telebot/__init__.py", line 417, in polling
    self.__non_threaded_polling(none_stop, interval, timeout)
  File "/Library/Frameworks/Python.framework/Versions/3.8/lib/python3.8/site-packages/telebot/__init__.py", line 468, in __non_threaded_polling
    self.__retrieve_updates(timeout)
  File "/Library/Frameworks/Python.framework/Versions/3.8/lib/python3.8/site-packages/telebot/__init__.py", line 281, in __retrieve_updates
    updates = self.get_updates(offset=(self.last_update_id + 1), timeout=timeout)
  File "/Library/Frameworks/Python.framework/Versions/3.8/lib/python3.8/site-packages/telebot/__init__.py", line 251, in get_updates
    json_updates = apihelper.get_updates(self.token, offset, limit, timeout, allowed_updates)
  File "/Library/Frameworks/Python.framework/Versions/3.8/lib/python3.8/site-packages/telebot/apihelper.py", line 199, in get_updates
    return _make_request(token, method_url, params=payload)
  File "/Library/Frameworks/Python.framework/Versions/3.8/lib/python3.8/site-packages/telebot/apihelper.py", line 62, in _make_request
    result = _get_req_session().request(method, request_url, params=params, files=files,
  File "/Library/Frameworks/Python.framework/Versions/3.8/lib/python3.8/site-packages/requests/sessions.py", line 530, in request
    resp = self.send(prep, **send_kwargs)
  File "/Library/Frameworks/Python.framework/Versions/3.8/lib/python3.8/site-packages/requests/sessions.py", line 643, in send
    r = adapter.send(request, **kwargs)
  File "/Library/Frameworks/Python.framework/Versions/3.8/lib/python3.8/site-packages/requests/adapters.py", line 510, in send
    raise ProxyError(e, request=request)
requests.exceptions.ProxyError: HTTPSConnectionPool(host='api.telegram.org', port=443): Max retries exceeded with url: /bot940145749:AAENwzTWDnBkbCXwJZ8Fw7XdS0GCM5CgZoU/getUpdates?offset=1&timeout=20 (Caused by ProxyError('Cannot connect to proxy.', OSError('Tunnel connection failed: 403 Forbidden')))
22.05.2020 14:23 - bot - INFO - Connect to a new proxy, ip – 218.241.219.84

22.05.2020 14:24 - bot - ERROR - Disconnected, geting new proxy
Traceback (most recent call last):
  File "/Library/Frameworks/Python.framework/Versions/3.8/lib/python3.8/site-packages/urllib3/connectionpool.py", line 667, in urlopen
    self._prepare_proxy(conn)
  File "/Library/Frameworks/Python.framework/Versions/3.8/lib/python3.8/site-packages/urllib3/connectionpool.py", line 930, in _prepare_proxy
    conn.connect()
  File "/Library/Frameworks/Python.framework/Versions/3.8/lib/python3.8/site-packages/urllib3/connection.py", line 316, in connect
    self._tunnel()
  File "/Library/Frameworks/Python.framework/Versions/3.8/lib/python3.8/http/client.py", line 894, in _tunnel
    (version, code, message) = response._read_status()
  File "/Library/Frameworks/Python.framework/Versions/3.8/lib/python3.8/http/client.py", line 264, in _read_status
    line = str(self.fp.readline(_MAXLINE + 1), "iso-8859-1")
  File "/Library/Frameworks/Python.framework/Versions/3.8/lib/python3.8/socket.py", line 669, in readinto
    return self._sock.recv_into(b)
socket.timeout: timed out

During handling of the above exception, another exception occurred:

Traceback (most recent call last):
  File "/Library/Frameworks/Python.framework/Versions/3.8/lib/python3.8/site-packages/requests/adapters.py", line 439, in send
    resp = conn.urlopen(
  File "/Library/Frameworks/Python.framework/Versions/3.8/lib/python3.8/site-packages/urllib3/connectionpool.py", line 724, in urlopen
    retries = retries.increment(
  File "/Library/Frameworks/Python.framework/Versions/3.8/lib/python3.8/site-packages/urllib3/util/retry.py", line 439, in increment
    raise MaxRetryError(_pool, url, error or ResponseError(cause))
urllib3.exceptions.MaxRetryError: HTTPSConnectionPool(host='api.telegram.org', port=443): Max retries exceeded with url: /bot940145749:AAENwzTWDnBkbCXwJZ8Fw7XdS0GCM5CgZoU/getUpdates?offset=1&timeout=20 (Caused by ProxyError('Cannot connect to proxy.', timeout('timed out')))

During handling of the above exception, another exception occurred:

Traceback (most recent call last):
  File "/Users/xalion/Desktop/spotibot_diploma/bot.py", line 100, in <module>
    bot.polling()
  File "/Library/Frameworks/Python.framework/Versions/3.8/lib/python3.8/site-packages/telebot/__init__.py", line 417, in polling
    self.__non_threaded_polling(none_stop, interval, timeout)
  File "/Library/Frameworks/Python.framework/Versions/3.8/lib/python3.8/site-packages/telebot/__init__.py", line 468, in __non_threaded_polling
    self.__retrieve_updates(timeout)
  File "/Library/Frameworks/Python.framework/Versions/3.8/lib/python3.8/site-packages/telebot/__init__.py", line 281, in __retrieve_updates
    updates = self.get_updates(offset=(self.last_update_id + 1), timeout=timeout)
  File "/Library/Frameworks/Python.framework/Versions/3.8/lib/python3.8/site-packages/telebot/__init__.py", line 251, in get_updates
    json_updates = apihelper.get_updates(self.token, offset, limit, timeout, allowed_updates)
  File "/Library/Frameworks/Python.framework/Versions/3.8/lib/python3.8/site-packages/telebot/apihelper.py", line 199, in get_updates
    return _make_request(token, method_url, params=payload)
  File "/Library/Frameworks/Python.framework/Versions/3.8/lib/python3.8/site-packages/telebot/apihelper.py", line 62, in _make_request
    result = _get_req_session().request(method, request_url, params=params, files=files,
  File "/Library/Frameworks/Python.framework/Versions/3.8/lib/python3.8/site-packages/requests/sessions.py", line 530, in request
    resp = self.send(prep, **send_kwargs)
  File "/Library/Frameworks/Python.framework/Versions/3.8/lib/python3.8/site-packages/requests/sessions.py", line 643, in send
    r = adapter.send(request, **kwargs)
  File "/Library/Frameworks/Python.framework/Versions/3.8/lib/python3.8/site-packages/requests/adapters.py", line 510, in send
    raise ProxyError(e, request=request)
requests.exceptions.ProxyError: HTTPSConnectionPool(host='api.telegram.org', port=443): Max retries exceeded with url: /bot940145749:AAENwzTWDnBkbCXwJZ8Fw7XdS0GCM5CgZoU/getUpdates?offset=1&timeout=20 (Caused by ProxyError('Cannot connect to proxy.', timeout('timed out')))
22.05.2020 14:24 - bot - INFO - Connect to a new proxy, ip – 163.172.180.18

22.05.2020 14:26 - bot - ERROR - Disconnected, geting new proxy
Traceback (most recent call last):
  File "/Library/Frameworks/Python.framework/Versions/3.8/lib/python3.8/site-packages/urllib3/connectionpool.py", line 667, in urlopen
    self._prepare_proxy(conn)
  File "/Library/Frameworks/Python.framework/Versions/3.8/lib/python3.8/site-packages/urllib3/connectionpool.py", line 930, in _prepare_proxy
    conn.connect()
  File "/Library/Frameworks/Python.framework/Versions/3.8/lib/python3.8/site-packages/urllib3/connection.py", line 316, in connect
    self._tunnel()
  File "/Library/Frameworks/Python.framework/Versions/3.8/lib/python3.8/http/client.py", line 894, in _tunnel
    (version, code, message) = response._read_status()
  File "/Library/Frameworks/Python.framework/Versions/3.8/lib/python3.8/http/client.py", line 264, in _read_status
    line = str(self.fp.readline(_MAXLINE + 1), "iso-8859-1")
  File "/Library/Frameworks/Python.framework/Versions/3.8/lib/python3.8/socket.py", line 669, in readinto
    return self._sock.recv_into(b)
socket.timeout: timed out

During handling of the above exception, another exception occurred:

Traceback (most recent call last):
  File "/Library/Frameworks/Python.framework/Versions/3.8/lib/python3.8/site-packages/requests/adapters.py", line 439, in send
    resp = conn.urlopen(
  File "/Library/Frameworks/Python.framework/Versions/3.8/lib/python3.8/site-packages/urllib3/connectionpool.py", line 724, in urlopen
    retries = retries.increment(
  File "/Library/Frameworks/Python.framework/Versions/3.8/lib/python3.8/site-packages/urllib3/util/retry.py", line 439, in increment
    raise MaxRetryError(_pool, url, error or ResponseError(cause))
urllib3.exceptions.MaxRetryError: HTTPSConnectionPool(host='api.telegram.org', port=443): Max retries exceeded with url: /bot940145749:AAENwzTWDnBkbCXwJZ8Fw7XdS0GCM5CgZoU/getUpdates?offset=1&timeout=20 (Caused by ProxyError('Cannot connect to proxy.', timeout('timed out')))

During handling of the above exception, another exception occurred:

Traceback (most recent call last):
  File "/Users/xalion/Desktop/spotibot_diploma/bot.py", line 100, in <module>
    bot.polling()
  File "/Library/Frameworks/Python.framework/Versions/3.8/lib/python3.8/site-packages/telebot/__init__.py", line 417, in polling
    self.__non_threaded_polling(none_stop, interval, timeout)
  File "/Library/Frameworks/Python.framework/Versions/3.8/lib/python3.8/site-packages/telebot/__init__.py", line 468, in __non_threaded_polling
    self.__retrieve_updates(timeout)
  File "/Library/Frameworks/Python.framework/Versions/3.8/lib/python3.8/site-packages/telebot/__init__.py", line 281, in __retrieve_updates
    updates = self.get_updates(offset=(self.last_update_id + 1), timeout=timeout)
  File "/Library/Frameworks/Python.framework/Versions/3.8/lib/python3.8/site-packages/telebot/__init__.py", line 251, in get_updates
    json_updates = apihelper.get_updates(self.token, offset, limit, timeout, allowed_updates)
  File "/Library/Frameworks/Python.framework/Versions/3.8/lib/python3.8/site-packages/telebot/apihelper.py", line 199, in get_updates
    return _make_request(token, method_url, params=payload)
  File "/Library/Frameworks/Python.framework/Versions/3.8/lib/python3.8/site-packages/telebot/apihelper.py", line 62, in _make_request
    result = _get_req_session().request(method, request_url, params=params, files=files,
  File "/Library/Frameworks/Python.framework/Versions/3.8/lib/python3.8/site-packages/requests/sessions.py", line 530, in request
    resp = self.send(prep, **send_kwargs)
  File "/Library/Frameworks/Python.framework/Versions/3.8/lib/python3.8/site-packages/requests/sessions.py", line 643, in send
    r = adapter.send(request, **kwargs)
  File "/Library/Frameworks/Python.framework/Versions/3.8/lib/python3.8/site-packages/requests/adapters.py", line 510, in send
    raise ProxyError(e, request=request)
requests.exceptions.ProxyError: HTTPSConnectionPool(host='api.telegram.org', port=443): Max retries exceeded with url: /bot940145749:AAENwzTWDnBkbCXwJZ8Fw7XdS0GCM5CgZoU/getUpdates?offset=1&timeout=20 (Caused by ProxyError('Cannot connect to proxy.', timeout('timed out')))
22.05.2020 14:27 - bot - INFO - Connect to a new proxy, ip – 45.250.226.47

22.05.2020 15:11 - TeleBot - ERROR - A request to the Telegram API was unsuccessful. The server returned HTTP 400 Bad Request. Response body:
[b'{"ok":false,"error_code":400,"description":"Bad Request: failed to get HTTP URL content"}']\n
22.05.2020 15:11 - TeleBot - ERROR - A request to the Telegram API was unsuccessful. The server returned HTTP 400 Bad Request. Response body:
[b'{"ok":false,"error_code":400,"description":"Bad Request: host is invalid"}']\n
